Workbook

Sheet PART I (CY 2025 & SY2025-2026)
B2: OFFICE PERFORMANCE COMMITMENT AND REVIEW FORM (OPCRF) ver.Feb2025
B4: Name of Employee: | N4: Verifier: | O4: EVA M. DOLLOSA RN
B5: Position/Designation: | N5: Position: | O5: OIC-Asst. Schools Division Superintendent
B6: Review Period: | N6: Approving Authority: | O6: FERDINAND S. SY PhD, CESO VI
B7: Strand/Bureau/Center/Service/Region/Division: | N7: Date of Review:
B8: Strand/Bureau/Center/Service/Region/Division Statement of Purpose: | F8: Anchored on the Vision, Mission, and Core Values of the Department of Education, I commit to providing quality, accessible, relevant, and liberating basic education for all learners. As a School Head, I shall uphold integrity, excellence, and accountability in leading the school community toward the achievement of educational goals and improved learner outcomes.I further commit to fostering a learner-centered environment, empowering teachers and stakeholders through collaboration and shared leadership, and ensuring effective implementation of programs, policies, and initiatives that promote holistic development and continuous school improvement. Through professionalism and dedication, I shall embody the core values of Maka-Diyos, Makatao, Makakalikasan, at Makabansa in the discharge of my duties and responsibilities.
B10: PART I-A: COMMITMENT TO ORGANIZATIONAL OUTCOMES (60%) Part I-A. Commitment to Organizational Outcomes shall capture office commitments, performance, and accomplishments based on office mandates and KRAs as reflected in the official issuance on the Compendium of Office Functions. This part shall capture the contributions of the office directly targeting the Organizational Outcomes indicated in the General Appropriation Act (GAA) Programs/Subprograms, Basic Education Development Plan (BEDP) Pillars, Current Administration Agenda, and other national level commitments that are aligned with and relevant to the office KRAs. Clear attribution shall be made to ensure such alignment.
B12: TO BE ACCOMPLISHED DURING PLANNING | S12: TO BE FILLED DURING EVALUATION
B13: Organizational Outcomes Alignment | F13: Objectives (based on Office Functions) | H13: Timeline | I13: Weight Allocation | J13: Performance Targets (Target Outcome/Ouput of the Bureau/Center/Service/Division aligned with the Outcome/Output Indicators in the Organizational Outcomes) | L13: Performance Measure (Quality, Efficiency, Timeliness) | M13: Rating Scale | R13: Means of Verification (MOVs) | S13: Actual Accomplishments | T13: RATING (Q,E,T) | U13: AVERAGE (QET) | V13: WEIGHTED AVERAGE
B14: Key Result Areas (KRA) (Based on Office Mandate and Functions) | C14: Organizational Outcome Attribution (Refer to the GAA Programs/Subprogram and BEDP Pillars) | J14: Value (numerical, statistical, trend) | K14: Description (expected outcome/ output/service) | M14: 5 (Outstanding) | N14: 4 (Very Satisfactory) | O14: 3 (Satisfactory) | P14: 2 (Unsatisfactory) | Q14: 1 (Poor)
C15: GAA Programs/ Subprograms | D15: BEDP Pillars | E15: Current Administration Agenda
B16: Education Human Resource Development Program | E16: X number of policies formulated, reviewed, and issued | F16: Human Resource Development | G16: Objective 1: Ensured preparation of HR policies, guidelines, and standards that are Bureau-initiated, or may be assigned by the EXECOM for issuance; compliant with PRIME-HRM standards and national guidelines geared towards competency-based HR system within the set scheduled deadline. | H16: January to December 2024 | I16: 0.35 | L16: Quality | M16: Met all 5 indicators based on the established standards in policy formulation: a. Consistent with existing laws, policies, guidelines, requirements, and data/information as may be required by law, oversight agencies, and/or DepEd b. Consistent with agency strategic directions and appropriate with DepEd context c. Compliant with DepEd guidelines on policy development process and underwent consultations and involvement of relevant management officials, personnel, and stakeholders at all governance levels d. Provided presentation materials, press release(as needed), and briefers for Directors and Executive sponsors e. Provided with complete staff work, to include implications/scenario analysis and recommendations | N16: Met 4 out of 5 indicators based on the established standards in policy formulation | O16: Met 3 out of 5 indicators based on the established standards in policy formulation | P16: Met 2 out of 5 indicators based on the established standards in policy formulation | Q16: Only 1 out of 5 indicators is met based on the established standards in policy formulation | S16: Policy deliverables submitted followed the set standards in policy formulation and met all 5 indicators | T16: 5 | U16: =AVERAGE(T16:T18) -> 4.6666667
L17: Efficiency | M17: 100% of total number of policy deliverables submitted and/or presented to the Director for approval; commented upon by such and provided responses to said comments; and/or integrated into the proposed policy action document. | N17: 76-99% of total number of policy deliverables submitted and/or presented to the Director for approval; commented upon by such and provided responses to said comments; and/or integrated into the proposed policy action document. | O17: 51-75% of total number of policy deliverables submitted and/or presented to the Director for approval; commented upon by such and provided responses to said comments; and/or integrated into the proposed policy action document. | P17: 26-50% of total number of policy deliverables submitted and/or presented to the Director for approval; commented upon by such and provided responses to said comments; and/or integrated into the proposed policy action document. | Q17: 25 %and below of total number of policy deliverables submitted and/or presented to the Director for approval; commented upon by such and provided responses to said comments; and/or integrated into the proposed policy action document. | S17: 13 out of 15 (87%) policy deliverables were submitted and/or presented to the Director and/or EXECOM for approval | T17: 4
L18: Timeliness | M18: Endorsed to the Office of the Director before the deadline set | N18: Endorsed to the Office of the Director on the deadline set | O18: Endorsed to the Office of the Director two weeks after the deadline | P18: Endorsed to the Office of the Director one month after the deadline | Q18: Endorsed to the Office of the Director more than one month | S18: 13 policy deliberables endorsed to the Office of the Director before the deadline set | T18: 5
B19: School Leadership and Administration | C19: Basic Education | D19: Pillar 1: Access Pillar 2: Equity Pillar 3: Quality | E19: 1. High Performing Teachers 2. Learners’ physical and mental well-being protection 3. Efficient and supportive governance structure 4. High Quality Education | F19: Implemented the School Improvement Plan (SIP) through Work and Financial Plan (WFP) and Annual Implementation Plan (AIP). | I19: 0.05 | J19: 2 | K19: AIP activities aligned with the approved WFP and SIP | L19: Quality | M19: Approved activities completed are: a. leading towards attainment of key deliverables b. carefully designed to suit school expectations c. complete with necessary evidence requirements d. activity outputs served as reference to ensure timeliness of key deliverables | N19: Approved activities are completed with documented non-compliance to any one (1) of the critical elements in items a, b, c, and d. | O19: Approved activities are completed with documented non-compliance to any one (2) of the critical elements in items a, b, c, and d. | P19: Approved activities are completed with documented non-compliance to any one (3) of the critical elements in items a, b, c, and d. | Q19: Approved activitie are completed with documented non-compliance to all the critical elements in items a, b, c, and d. | R19: Approved Work and Financial Plan (WFP) and Annual Implementation Plan (AIP) | S19: 1 Work and Financial Plan (WFP) 1 Annual Implementation Plan (AIP) | U19: =AVERAGE(T19:T21) -> #DIV/0! | V19: =U19*I19 -> #DIV/0!
L20: Efficiency | M20: All or 91-100% of AIP activities aligned with the approved SIP through Work and Financial Plan (WFP) and Annual Implementation Plan (AIP).are conducted/ implemented | N20: 76-90% of AIP activities aligned with the approved SIP through Work and Financial Plan (WFP) and Annual Implementation Plan (AIP).are conducted/ implemented | O20: 51-75%of AIP activities aligned with the approved SIP through Work and Financial Plan (WFP) and Annual Implementation Plan (AIP).are conducted/ implemented | P20: 26-50% of AIP activities aligned with the approved SIP through Work and Financial Plan (WFP) and Annual Implementation Plan (AIP).are conducted/ implemented | Q20: 0-25% of AIP activities aligned with the approved SIP through Work and Financial Plan (WFP) and Annual Implementation Plan (AIP).are conducted/ implemented
L21: Timeliness | M21: Completed activities are ahead the targeted period of conduct | N21: Completed activities are within the targeted period of conduct | O21: Completed activities with a delay of one (1) month from the targeted period of conduct | P21: Completed activities with a delay of one (1) quarter from the targeted period of conduct | Q21: Completed activities with a delay of one (1) semester from the targeted period of conduct
C22: Inclusive Education | D22: Pillar 3: Quality | E22: 1. High Performing Teachers 4. High Quality Education | F22: Implemented Instructional Supervision in the delivery and/or implementation of learning modalities | I22: 0.05 | J22: 10 | K22: Instructional Supervision Plans | L22: Quality | M22: Submitted ISPs to address school instuction improvement needs with the following indicators: a. Timeline b. Key Focus Area c. Target Teachers d. IS Strategies/activities | N22: Submitted ISPs to address school instuction improvement needs with 3 indicators only | O22: Submitted ISPs to address school instuction improvement needs with 2 indicators only | P22: Submitted ISPs to address school instuction improvement needs with 1 indicators only | Q22: No submitted ISPs to address school instuction improvement needs | R22: Approved ISP Approved MISAR | S22: Approved ISP Approved MISAR | U22: =AVERAGE(T22:T24) -> #DIV/0! | V22: =U22*I22 -> #DIV/0!
L23: Efficiency | M23: 10 ISPs Approved | N23: 9 ISPs Approved | O23: 8 ISPs Approved | P23: 7 ISPs Approved | Q23: less than 6 ISPs Approved
L24: Timeliness | M24: ISPs were submitted 5 days before the implementation | N24: ISPs were submitted 3 days before the implementation | O24: ISPs were submitted 2 days before the implementation | P24: ISPs were submitted 1 days before the implementation | Q24: No submission of IS for the month
C25: Support to Learners and Schools | D25: Enabling Mechanism | E25: 3. Efficient and supportive governance | F25: Established and sustained functional partnerships with stakeholders, evidenced by implemented collaborative programs, signed agreements, and documented support that contribute to improved learner outcomes. | I25: 0.05 | J25: 10 | K25: Signed Memoranda of Agreement (MOA) / Deed of Donation / Partnership Agreements | L25: Quality | M25: At least 5 MOAs/Deed of Donation/Partnership Agreement | N25: At least 4 MOAs/Deed of Donation/Partnership Agreement | O25: At least 3 MOAs/Deed of Donation/Partnership Agreement | P25: At least 2 MOAs/Deed of Donation/Partnership Agreement | Q25: At least 1 MOAs/Deed of Donation/Partnership Agreement | R25: Executed and duly signed Memoranda of Agreement (MOA), Deeds of Donation, and Partnership Agreements | S25: Executed and duly signed Memoranda of Agreement (MOA), Deeds of Donation, and Partnership Agreements | U25: =AVERAGE(T25:T27) -> #DIV/0! | V25: =U25*I25 -> #DIV/0!
L26: Efficiency | M26: Total amount genreated from partners/donors engaged/involved in the school activities/programs/projects annually: (Php 30,000 and above) | N26: Total amount generated from partners/donors engaged/involvedin the school activities/programs/projects annually: (Php 25,000-29,999.00) | O26: Total amount generated from partners/donors engaged/involvedin the school activities/programs/projects annually: (Php 20,000 - 24,999.00) | P26: Total amount generated from partners/donors engaged/involvedin the school activities/programs/projects annually: (Php 15,000 - 19, 999.00) | Q26: Total amount generated from partners/donors engaged/involvedin the school activities/programs/projects annually: (Php 14,999.00 and below)
L27: Timeliness | M27: All Reports Inventory of Partners submitted to Soc Mob without delay | N27: Any 1 delayed submission | O27: Any 2 delayed submission | P27: Any 3 delayed submissions | Q27: 4 or more delayed submissions
M28: 95-119 partners/donors engaged/involvedin the school activities/programs/projects annually - 4 pts | O28: Php 10,000-14,999 - 3 pts
O29: Php 5,000-9,999 - 2 pts
M30: 75-94 partners/donors engaged/involved in the school activities/programs/projects annually - 3 pts | O30: Below Php 5,000 - 1 pt
M32: 55-74 partners/donors engaged/involved in the school activities/programs/projects annually - 2 pts
M34: less than 55 partners/donors engaged/involved in the school activities/programs/projects annually - 1 pt
B37: Teaching and Lerning Delivery | C37: Support to Schools and Learners Program | D37: Pillar 3: Quality | E37: Raise education Quality through Upgraded Curriculum, Modernized Assessment and Digitally Enabled Schools | F37: Achieved 100% Promotion Rate of Learners in Elementary/Secondary/Integrated Schools | I37: 0.03 | J37: 1 | K37: Promotion Rate | L37: Quality | M37: Achieved 100% Promotion Rate | N37: Achieved 76%-99% Promotion Rate | O37: Achieved 51%-75% Promotion Rate | P37: Achieved 26%-50% Promotion Rate | Q37: Achieved 1%-25% Promotion Rate | R37: Report on Promotion Rate (School Form 6) | S37: Report on Promotion Rate (SF6) stamped received and signed by appropriate signatories. | U37: =AVERAGE(T37:T39) -> #DIV/0! | V37: =U37*I37 -> #DIV/0!
L38: Efficiency
L39: Timeliness | M39: Submitted Report on Promotion on or before the deadline | N39: Submitted Report on Promotion 1-3 days after the deadline | O39: Submitted Report on Promotion 4-5 days after the deadline | P39: Submitted Report on Promotion 6-7 days after the deadline | Q39: No Submitted Report
C40: Support to Schools and Learners Program | D40: Pillar 3: Quality | E40: Raise education Quality through Upgraded Curriculum, Modernized Assessment and Digitally Enabled Schools | F40: Achieved 100% Completion Rate of Learners in Elementary/Secondary/Integrated Schools | I40: 0.03 | J40: 1 | K40: Graduation Rate | L40: Quality | M40: Achieved 100% Graduation Rate | N40: Achieved 76%-99% Graduation Rate | O40: Achived 51%-75% Graduation Rate | P40: Achieved 26%-50% Graduiation Rate | Q40: Achieved 1%-25% Graduation Rate | R40: Report on Graduation Rate (Sf 6)stamped received and signed by appropriate signatories. | S40: Report on Graduation Rate (SF6) stamped received and signed by appropriate signatories. | U40: =AVERAGE(T40:T42) -> #DIV/0! | V40: =U40*I40 -> #DIV/0!
L41: Efficiency
L42: Timeliness | M42: Submitted Report on Graduation on deadline | N42: Submitted Report on Graduation 1-3 days after the deadline | O42: Submitted Report on Completion 4-5 days after the deadline | P42: Submitted Report on Completion 6-7 days after the deadline | Q42: Report on Graduation was not submitted
C43: Support to Schools and Learners Program | D43: Pillar 3: Quality | E43: Raise education Quality through Upgraded Curriculum, Modernized Assessment and Digitally Enabled Schools | F43: Improved the Quarterly Assessment Result in Elementary/Secondary/ Integrated School | I43: 0.04 | J43: 4 (1 per quarter) | K43: Quarterly Assessment with Analysis | L43: Quality | M43: Achieved 80-100% MPS result with analysis | N43: Achieved 70%-79% MPS result with analysis | O43: Achieved 50%-69% MPS Result with Analysis | P43: Achieved 30%-49% MPS Result with Analysis | Q43: Achieved 0%-29% MPS Result with Analysis | R43: Reports on MPS with Analysis | S43: Reports on MPS with Analysis stamped received and signed by appropriate signatories. | U43: =AVERAGE(T43:T45) -> #DIV/0! | V43: =U43*I43 -> #DIV/0!
L44: Efficiency | M44: Submitted 4 Quarterly Reports | N44: Submitted 3 Quarterly Reports | O44: Submitted 2 Quarterly Reports | P44: Submitted 1 Quarterly Report | Q44: No Report submitted
L45: Timeliness | M45: MPS Result with Analysis were submitted 5 days before the deadline | N45: MPS Result with Analysis were submitted 3 days before the deadline | O45: MPS Result with Analysis were submitted on the deadline | P45: MPS Result with Analysis were submitted on the deadline | Q45: MPS Result with Analysis were not submitted
C46: Education Policy Deveopment Program | D46: Pillar 1: Access Pillar 2: Equity Pillar 3: Quality | E46: 1. High Performing Teachers 2. Learners’ physical and mental well-being protection 3. Efficient and supportive governance structure 4. High Quality Education | F46: Conducted educational research based on the results of assessments | I46: 0.05 | J46: 1 | K46: Crafted action research/basic resarch for policy brief. | L46: Quality | M46: Conducted action research with the ff indicators: 1. Conducted and completed a well-structured research directly anchored on assessment results addressing a major learning or performance gap. 2. Validated and presented/published in a division, regional, or national research forum. 3. Findings were utilized for SIP/AIP, instructional supervision, or program enhancement. 4. Provided mentoring or coaching to teachers on research writing or implementation. | N46: 1. Completed a well-documented research aligned with assessment results. 2. Validated or approved by the Division Research Committee. 3. Findings were used to improve instruction or learner performance. | O46: 1. Completed a research study based on assessment data. 2. Findings were shared with teachers for instructional improvement. | P46: 1. Submitted an incomplete or weakly aligned research output with limited linkage to assessment data. | Q46: 1. Failed to conduct or submit any research output. | R46: Approved Research Proposal and Final Report • Division/School Research Committee Validation Form • Certificate of Presentation/Publication • SIP/AIP Integration or Utilization Report • Mentoring/Coaching Documentation | S46: Approved Research Proposal and Final Report • Division/School Research Committee Validation Form • Certificate of Presentation/Publication • SIP/AIP Integration or Utilization Report • Mentoring/Coaching Documentation | U46: =AVERAGE(T46:T48) -> #DIV/0! | V46: =U46*I46 -> #DIV/0!
L47: Efficiency | M47: 1. Conducted the research with efficient use of time, data, and resources, meeting all standards. 2. Demonstrated initiative and leadership by guiding other teachers or forming a school research team. 3. Produced outputs beyond expectations (e.g., supplementary materials, posters, or digital resources). 4. Ensured accuracy and coherence of results, requiring no major revisions. | N47: 1. Conducted research independently and efficiently within planned timelines and available resources. 2. Completed with minor revisions after validation. 3. Results were applied to improve learning delivery or school management. | O47: 1. Conducted the research with some supervision. 2. Utilized resources adequately and met minimum standards. | P47: Required close supervision and multiple corrections before completion. | Q47: Failed to complete or manage research activities despite available support.
L48: Timeliness | M48: 1. Research was completed, validated, and disseminated ahead of schedule. 2. Results integrated immediately into SIP/AIP or teaching plans. 3. Findings were presented or shared within the same school year. 4. Demonstrated proactive submission and utilization of findings. | N48: 1. Research completed and submitted on or before the target deadline. 2. Findings disseminated for school-level utilization. 3. Results aligned with division timelines. | O48: 1. Research completed slightly beyond deadline but still relevant and utilized. 2. Findings partially disseminated or used. | P48: Research submitted significantly late, limiting its usefulness for current school planning. | Q48: No research submitted or dissemination conducted within the evaluation period
...

Sheet PART II
B2: DepEd OPCRF (ver.Feb2025), page 2 of 4
B3: PART II-A: LEADERSHIP COMPETENCIES (2.5%) Part II-A. Leadership Competencies shall capture competencies expected of heads of functional offices who hold managerial and executive/supervisory positions. The Leadership Competencies expected to be demonstrated include Leading People, People Performance Management, and People Development.
B4: Competencies | C4: Behavioural Indicators | G4: Remarks/ Observations | I4: RATING | J4: AVERAGE | L4: DepEd Competencies Scale
L5: Numerical Rating | M5: Adjectival Rating | N5: Definition
B6: Leading People | C6: 1. Uses basic persuasion techniques in a discussion or presentation e.g., staff mobilization, appeals to reason and/or emotions, uses data and examples, visual aids | J6: =AVERAGE(I6:I10) -> #DIV/0! | L6: 5 | M6: Role Model | N6: Behavioral indicator is consistently exhibited and is worthy of emulation.
C7: 2. Persuades, convinces or influences others, in order to have a specific impact or effect. | L7: 4 | M7: Consistently Demonstrated | N7: Behavioral indicator is constantly shown.
C8: 3. “Sets a good example”, is a credible and respected leader; and demonstrates desired behavior. | L8: 3 | M8: Most of the Time Demonstrated | N8: Behavioral indicator is often shown.
C9: 4. Forwards personal, professional and work unit needs and interests in an issue. | L9: 2 | M9: Sometimes Demonstrated | N9: Behavioral indicator is irregularly shown.
C10: 5. Assumes a pivotal role in promoting the development of an inspiring, relevant vision for the organization and influences others to share ownership of DepEd goals, in order to create an effective work environment. | L10: 1 | M10: Rarely Demonstrated | N10: Behavioral indicator is seldom shown.
B11: People Performance Management | C11: 1. Makes specific changes in the performance management system or in own work methods to improve performance (e.g. does something better, faster, at lower cost, more efficiently; improves quality, customer satisfaction, morale, revenues). | J11: =AVERAGE(I11:I15) -> #DIV/0!
C12: 2. Sets performance standards and measures progress of employees based on office and department targets.
C13: 3. Provides feedback and technical assistance such as coaching for performance improvement and action planning.
C14: 4. States performance expectations clearly and checks understanding and commitment.
C15: 5. Performs all the stages of result-based performance management system supported by evidence and required documents/forms.
B16: People Development | C16: 1. Improves the skills and effectiveness of individuals through employing a range of development strategies. | J16: =AVERAGE(I16:I20) -> #DIV/0!
C17: 2. Facilitates workforce effectiveness through coaching and motivating/developing people within a work environment that promotes mutual trust and respect.
C18: 3. Conceptualizes and implements learning interventions to meet identified training needs.
C19: 4. Does long-term coaching or training by arranging appropriate and helpful assignments, formal training, or other experiences for the purpose of supporting a person’s learning and development.
C20: 5. Cultivates a learning environment by structuring interactive experiences such as looking for future opportunities that are in support of achieving individual career goals.
B21: Part II-A Total Score: Weighted Average (Average x 0.025) | J21: =AVERAGE(J6:J20)*0.025 -> #DIV/0!
B22: PART II-B: CORE BEHAVIOURAL COMPETENCIES (2.5%) Part II-B. Core Behavioral Competencies shall capture competencies required from all DepEd personnel in all job groups within the organization, upholding the DepEd’s core values and the Code of Conduct and Ethical Standards for Public Officials and Employees pursuant to RA 6713. They represent the way individuals embody and live the values of the organization.
B23: Competencies | C23: Behavioural Indicators | G23: Remarks/ Observations | I23: RATING | J23: AVERAGE
B25: Self-Management | C25: 1. Sets personal goals and direction, needs and development. | J25: =AVERAGE(I25:I29) -> #DIV/0!
C26: 2. Understands personal actions and behavior that are clear and purposive and takes into account personal goals and values congruent to that of the organization
C27: 3. Displays emotional maturity and enthusiasm for and is challenged by higher goals
C28: 4. Prioritize work tasks and schedules (through Gantt charts, checklists, etc.) to achieve goals
C29: 5. Sets high quality, challenging, realistic goals for self and others.
B30: Professionalism and Ethics | C30: 1. Demonstrate the values and behavior enshrined in the Norms and Conduct and Ethical Standards for Public Officials and Employees (RA 6713). | J30: =AVERAGE(I30:I34) -> #DIV/0!
C31: 2. Practice ethical and professional behavior and conduct taking into account the impact of his/her actions and decisions.
C32: 3. Maintains a professional image: being trustworthy, regularity of attendance and punctuality, good grooming and communication.
C33: 4. Makes personal sacrifices to meet the organization’s needs.
C34: 5. Act with a sense of urgency and responsibility to meet the organization’s needs, improve system and help others improve their effectiveness.
B35: Results Focus | C35: 1. Achieves results with optimal use of time and resources mist of the time. | J35: =AVERAGE(I35:I39) -> #DIV/0!
C36: 2. Avoids rework, mistakes and wastage through effective work methods by placing organizational needs before personal needs.
C37: 3. Delivers error-free outputs most of the time by conforming to standard operating procedures correctly and consistently. Able to produce very satisfactory quality of work in terms of usefulness/acceptability and completeness with no supervision required.
C38: 4. Expresses a desire to do better and may express frustration at waste or inefficiency. May focus on new or more precise ways of meeting goals set
C39: 5. Makes specific changes in the system or in own work methods to improve performance. Examples may include doing something better, faster, at a lower cost, more efficiently, or improving quality, customer satisfaction, morale, without setting any specific goal.
B40: Teamwork | C40: 1. Willingly does his/her share of responsibility | J40: =AVERAGE(I40:I44) -> #DIV/0!
C41: 2. Promotes collaboration and removes barriers to teamwork and goal accomplishment across the organization.
C42: 3. Applies negotiation principles in arriving at win-win agreements.
...

Sheet PART III
B1: DepEd OPCRF (ver.Feb2025), page 3 of 4
C2: PART III: SUMMARY OF RATINGS
C5: Final Performance Components | E5: Weight Allocation | F5: Obtained Score | G5: Overall Score | H5: RPMS Rating | M5: RPMS Rating Table
H6: Numerical Rating | I6: Adjectival Rating | M6: Range | N6: Numerical Rating | O6: Adjectival Rating
C7: PART I | D7: A. Commitment to Organizational Outcomes | E7: 0.6 | F7: ='PART I (CY 2025 & SY2025-2026)'!V76 -> #DIV/0! | G7: =SUM(F$7:F$11) -> #DIV/0! | M7: 4.500-5.000 | N7: 5 | O7: Outstanding
D8: B. Innovating and Intervening Accomplishments | E8: 0.2 | F8: ='PART I (CY 2025 & SY2025-2026)'!V112 -> #DIV/0! | M8: 3.500-4.499 | N8: 4 | O8: Very Satisfactory
D9: C. Organizational Effectiveness | E9: 0.15 | F9: ='PART I (CY 2025 & SY2025-2026)'!V146 -> #DIV/0! | M9: 2.500-3.499 | N9: 3 | O9: Satisfactory
C10: PART II | D10: A. Leadership Competencies | E10: 2.5% (0.125) | F10: ='PART II'!J21 -> #DIV/0! | M10: 1.500-2.499 | N10: 2 | O10: Unsatisfactory
D11: B. Core Behavioural Competencies | E11: 2.5% (0.125) | F11: ='PART II'!J55 -> #DIV/0! | M11: 1.000-1.499 | N11: 1 | O11: Poor
C13: Ratee-Rater Agreement
C15: The signatures below confirm that the employee and his/her superior have agreed to the contents of the performance as captured in this form.
C17: Name of Employee: ARCHY MAR P. AGUILAR | F17: Name of Superior: EVA M. DOLLOSA RN
C19: Signature: | F19: Signature:
C21: Date: | F21: Date:

Sheet PART IV
C2: DepEd OPCRF (ver.Feb2025), page 4 of 4
C4: PART IV: IMPROVEMENT AND DEVELOPMENT PLANS
C6: Part IV-A: Office Improvement Plan
E7: Action Plan
C8: Gap Analysis (SWOT) | D8: Improvement Area | E8: General Objective | G8: Recommended Improvement Intervention | I8: Timeline | J8: Resources Needed
C13: Feedback:
C15: Part IV-B: Individual Development Plan
E16: Action Plan
C17: Strengths | D17: Improvement Needs | E17: Learning Objective (based on the developmental intervention) | G17: Recommended Developmental Intervention | I17: Timeline | J17: Resources Needed
C23: Feedback:
F25: EVA M. DOLLOSA RN | I25: FERDINAND S. SY PhD, CESO VI
C26: RATEE | F26: RATER | I26: APPROVING AUTHORITY
